2025-04-08 16:03:53   main.py --matcher duster --max_num_keypoints 2048 --img_size 512 --data_dir data --log_dir out_sift-lg --save_images --device cuda
2025-04-08 16:03:53   Arguments: Namespace(matcher='duster', max_num_keypoints=2048, num_iterations=4, img_size=512, save_images=True, device='cuda', data_dir='data', log_dir='out_sift-lg')
2025-04-08 16:03:53   The outputs are being saved in logs/out_sift-lg/2025-04-08_16-03-53
2025-04-08 16:03:53   
Traceback (most recent call last):
  File "/gpfs/home3/scur2410/EarthMatch_Master_Duster/main.py", line 53, in <module>
    matcher = get_matcher(args.matcher, device=args.device, max_num_keypoints=args.max_num_keypoints)
  File "/gpfs/home3/scur2410/EarthMatch_Master_Duster/image-matching-models/matching/utils.py", line 158, in wrapper
    return func(*a, **ka)
  File "/gpfs/home3/scur2410/EarthMatch_Master_Duster/image-matching-models/matching/__init__.py", line 216, in get_matcher
    from matching.im_models import duster
  File "/gpfs/home3/scur2410/EarthMatch_Master_Duster/image-matching-models/matching/im_models/duster.py", line 14, in <module>
    from dust3r.model import AsymmetricCroCo3DStereo
  File "/gpfs/home3/scur2410/EarthMatch_Master_Duster/dust3r/model.py", line 14, in <module>
    from .heads import head_factory
  File "/gpfs/home3/scur2410/EarthMatch_Master_Duster/dust3r/heads/__init__.py", line 8, in <module>
    from .dpt_head import create_dpt_head
  File "/gpfs/home3/scur2410/EarthMatch_Master_Duster/dust3r/heads/dpt_head.py", line 16, in <module>
    import dust3r.utils.path_to_croco  # noqa: F401
  File "/gpfs/home3/scur2410/EarthMatch_Master_Duster/dust3r/utils/path_to_croco.py", line 18, in <module>
    raise ImportError(f"croco is not initialized, could not find: {CROCO_MODELS_PATH}.\n "
ImportError: croco is not initialized, could not find: /gpfs/home3/scur2410/EarthMatch_Master_Duster/croco/models.
 Did you forget to run 'git submodule update --init --recursive' ?

