2025-04-08 15:49:02   main.py --matcher master --max_num_keypoints 2048 --img_size 512 --data_dir data --log_dir out_sift-lg --save_images --device cuda
2025-04-08 15:49:02   Arguments: Namespace(matcher='master', max_num_keypoints=2048, num_iterations=4, img_size=512, save_images=True, device='cuda', data_dir='data', log_dir='out_sift-lg')
2025-04-08 15:49:02   The outputs are being saved in logs/out_sift-lg/2025-04-08_15-49-02
2025-04-08 15:49:02   
Traceback (most recent call last):
  File "/gpfs/home3/scur2410/EarthMatch_Master_Duster/main.py", line 51, in <module>
    matcher = get_matcher(args.matcher, device=args.device, max_num_keypoints=args.max_num_keypoints)
  File "/gpfs/home3/scur2410/EarthMatch_Master_Duster/image-matching-models/matching/utils.py", line 158, in wrapper
    return func(*a, **ka)
  File "/gpfs/home3/scur2410/EarthMatch_Master_Duster/image-matching-models/matching/__init__.py", line 221, in get_matcher
    from matching.im_models import master
  File "/gpfs/home3/scur2410/EarthMatch_Master_Duster/image-matching-models/matching/im_models/master.py", line 11, in <module>
    from mast3r.model import AsymmetricMASt3R
  File "/gpfs/home3/scur2410/EarthMatch_Master_Duster/mast3r/model.py", line 11, in <module>
    from mast3r.catmlp_dpt_head import mast3r_head_factory
  File "/gpfs/home3/scur2410/EarthMatch_Master_Duster/mast3r/catmlp_dpt_head.py", line 11, in <module>
    import mast3r.utils.path_to_dust3r  # noqa
  File "/gpfs/home3/scur2410/EarthMatch_Master_Duster/mast3r/utils/path_to_dust3r.py", line 18, in <module>
    raise ImportError(f"dust3r is not initialized, could not find: {DUSt3R_LIB_PATH}.\n "
ImportError: dust3r is not initialized, could not find: /gpfs/home3/scur2410/EarthMatch_Master_Duster/dust3r/dust3r.
 Did you forget to run 'git submodule update --init --recursive' ?

